Workbook
Name Orders: Orders!$A$1:$U$9995
Name People: People!$A$1:$B$5
Name Returns: Returns!$C$1:$C$801
Name Срез_Category: #N/A
Name Срез_City: #N/A
Name Срез_Region: #N/A
Name Срез_Segment: #N/A
Name Срез_Sub_Category: #N/A
Name Срез_Годы: #N/A

Sheet Orders
A1: Row ID | B1: Order ID | C1: Order Date | D1: Ship Date | E1: Ship Mode | F1: Customer ID | G1: Customer Name | H1: Segment | I1: Country | J1: City | K1: State | L1: Postal Code | M1: Region | N1: Product ID | O1: Category | P1: Sub-Category | Q1: Product Name | R1: Sales | S1: Quantity | T1: Discount | U1: Profit | V1: Person | W1: Returnes | X1: Столбец1
A2: 1 | B2: CA-2018-152156 | C2: 43412 | D2: 43415 | E2: Second Class | F2: CG-12520 | G2: Claire Gute | H2: Consumer | I2: United States | J2: Henderson | K2: Kentucky | L2: 42420 | M2: South | N2: FUR-BO-10001798 | O2: Furniture | P2: Bookcases | Q2: Bush Somerset Collection Bookcase | R2: 261.96 | S2: 2 | T2: 0 | U2: 41.9136 | V2: =IF(M2=People!$B$2, People!$A$2, IF(M2=People!$B$3, People!$A$3, IF(M2=People!$B$4, People!$A$4, IF(M2=People!$B$5, People!$A$5, 0)))) -> Cassandra Brandow | W2: =IFERROR(VLOOKUP(Orders!$B2,Returns!$B:$C,2,0),"No") -> No | X2: =IFERROR((INDEX(Returns!$C$2:$C$801, MATCH(B2, Returns!$B$2:$B$801, 0))), "No") -> No
A3: 2 | B3: CA-2018-152156 | C3: 43412 | D3: 43415 | E3: Second Class | F3: CG-12520 | G3: Claire Gute | H3: Consumer | I3: United States | J3: Henderson | K3: Kentucky | L3: 42420 | M3: South | N3: FUR-CH-10000454 | O3: Furniture | P3: Chairs | Q3: Hon Deluxe Fabric Upholstered Stacking Chairs, Rounded Back | R3: 731.94 | S3: 3 | T3: 0 | U3: 219.582 | V3: =IF(M3=People!$B$2, People!$A$2, IF(M3=People!$B$3, People!$A$3, IF(M3=People!$B$4, People!$A$4, IF(M3=People!$B$5, People!$A$5, 0)))) -> Cassandra Brandow | W3: =IFERROR(VLOOKUP(Orders!$B3,Returns!$B:$C,2,0),"No") -> No | X3: =IFERROR((INDEX(Returns!$C$2:$C$801, MATCH(B3, Returns!$B$2:$B$801, 0))), "No") -> No
A4: 3 | B4: CA-2018-138688 | C4: 43263 | D4: 43267 | E4: Second Class | F4: DV-13045 | G4: Darrin Van Huff | H4: Corporate | I4: United States | J4: Los Angeles | K4: California | L4: 90036 | M4: West | N4: OFF-LA-10000240 | O4: Office Supplies | P4: Labels | Q4: Self-Adhesive Address Labels for Typewriters by Universal | R4: 14.62 | S4: 2 | T4: 0 | U4: 6.8714 | V4: =IF(M4=People!$B$2, People!$A$2, IF(M4=People!$B$3, People!$A$3, IF(M4=People!$B$4, People!$A$4, IF(M4=People!$B$5, People!$A$5, 0)))) -> Anna Andreadi | W4: =IFERROR(VLOOKUP(Orders!$B4,Returns!$B:$C,2,0),"No") -> No | X4: =IFERROR((INDEX(Returns!$C$2:$C$801, MATCH(B4, Returns!$B$2:$B$801, 0))), "No") -> No
A5: 4 | B5: US-2017-108966 | C5: 43019 | D5: 43026 | E5: Standard Class | F5: SO-20335 | G5: Sean O'Donnell | H5: Consumer | I5: United States | J5: Fort Lauderdale | K5: Florida | L5: 33311 | M5: South | N5: FUR-TA-10000577 | O5: Furniture | P5: Tables | Q5: Bretford CR4500 Series Slim Rectangular Table | R5: 957.5775 | S5: 5 | T5: 0.45 | U5: -383.031 | V5: =IF(M5=People!$B$2, People!$A$2, IF(M5=People!$B$3, People!$A$3, IF(M5=People!$B$4, People!$A$4, IF(M5=People!$B$5, People!$A$5, 0)))) -> Cassandra Brandow | W5: =IFERROR(VLOOKUP(Orders!$B5,Returns!$B:$C,2,0),"No") -> No | X5: =IFERROR((INDEX(Returns!$C$2:$C$801, MATCH(B5, Returns!$B$2:$B$801, 0))), "No") -> No
A6: 5 | B6: US-2017-108966 | C6: 43019 | D6: 43026 | E6: Standard Class | F6: SO-20335 | G6: Sean O'Donnell | H6: Consumer | I6: United States | J6: Fort Lauderdale | K6: Florida | L6: 33311 | M6: South | N6: OFF-ST-10000760 | O6: Office Supplies | P6: Storage | Q6: Eldon Fold 'N Roll Cart System | R6: 22.368 | S6: 2 | T6: 0.2 | U6: 2.5164 | V6: =IF(M6=People!$B$2, People!$A$2, IF(M6=People!$B$3, People!$A$3, IF(M6=People!$B$4, People!$A$4, IF(M6=People!$B$5, People!$A$5, 0)))) -> Cassandra Brandow | W6: =IFERROR(VLOOKUP(Orders!$B6,Returns!$B:$C,2,0),"No") -> No | X6: =IFERROR((INDEX(Returns!$C$2:$C$801, MATCH(B6, Returns!$B$2:$B$801, 0))), "No") -> No
A7: 6 | B7: CA-2016-115812 | C7: 42530 | D7: 42535 | E7: Standard Class | F7: BH-11710 | G7: Brosina Hoffman | H7: Consumer | I7: United States | J7: Los Angeles | K7: California | L7: 90032 | M7: West | N7: FUR-FU-10001487 | O7: Furniture | P7: Furnishings | Q7: Eldon Expressions Wood and Plastic Desk Accessories, Cherry Wood | R7: 48.86 | S7: 7 | T7: 0 | U7: 14.1694 | V7: =IF(M7=People!$B$2, People!$A$2, IF(M7=People!$B$3, People!$A$3, IF(M7=People!$B$4, People!$A$4, IF(M7=People!$B$5, People!$A$5, 0)))) -> Anna Andreadi | W7: =IFERROR(VLOOKUP(Orders!$B7,Returns!$B:$C,2,0),"No") -> No | X7: =IFERROR((INDEX(Returns!$C$2:$C$801, MATCH(B7, Returns!$B$2:$B$801, 0))), "No") -> No
A8: 7 | B8: CA-2016-115812 | C8: 42530 | D8: 42535 | E8: Standard Class | F8: BH-11710 | G8: Brosina Hoffman | H8: Consumer | I8: United States | J8: Los Angeles | K8: California | L8: 90032 | M8: West | N8: OFF-AR-10002833 | O8: Office Supplies | P8: Art | Q8: Newell 322 | R8: 7.28 | S8: 4 | T8: 0 | U8: 1.9656 | V8: =IF(M8=People!$B$2, People!$A$2, IF(M8=People!$B$3, People!$A$3, IF(M8=People!$B$4, People!$A$4, IF(M8=People!$B$5, People!$A$5, 0)))) -> Anna Andreadi | W8: =IFERROR(VLOOKUP(Orders!$B8,Returns!$B:$C,2,0),"No") -> No | X8: =IFERROR((INDEX(Returns!$C$2:$C$801, MATCH(B8, Returns!$B$2:$B$801, 0))), "No") -> No
A9: 8 | B9: CA-2016-115812 | C9: 42530 | D9: 42535 | E9: Standard Class | F9: BH-11710 | G9: Brosina Hoffman | H9: Consumer | I9: United States | J9: Los Angeles | K9: California | L9: 90032 | M9: West | N9: TEC-PH-10002275 | O9: Technology | P9: Phones | Q9: Mitel 5320 IP Phone VoIP phone | R9: 907.152 | S9: 6 | T9: 0.2 | U9: 90.7152 | V9: =IF(M9=People!$B$2, People!$A$2, IF(M9=People!$B$3, People!$A$3, IF(M9=People!$B$4, People!$A$4, IF(M9=People!$B$5, People!$A$5, 0)))) -> Anna Andreadi | W9: =IFERROR(VLOOKUP(Orders!$B9,Returns!$B:$C,2,0),"No") -> No | X9: =IFERROR((INDEX(Returns!$C$2:$C$801, MATCH(B9, Returns!$B$2:$B$801, 0))), "No") -> No
A10: 9 | B10: CA-2016-115812 | C10: 42530 | D10: 42535 | E10: Standard Class | F10: BH-11710 | G10: Brosina Hoffman | H10: Consumer | I10: United States | J10: Los Angeles | K10: California | L10: 90032 | M10: West | N10: OFF-BI-10003910 | O10: Office Supplies | P10: Binders | Q10: DXL Angle-View Binders with Locking Rings by Samsill | R10: 18.504 | S10: 3 | T10: 0.2 | U10: 5.7825 | V10: =IF(M10=People!$B$2, People!$A$2, IF(M10=People!$B$3, People!$A$3, IF(M10=People!$B$4, People!$A$4, IF(M10=People!$B$5, People!$A$5, 0)))) -> Anna Andreadi | W10: =IFERROR(VLOOKUP(Orders!$B10,Returns!$B:$C,2,0),"No") -> No | X10: =IFERROR((INDEX(Returns!$C$2:$C$801, MATCH(B10, Returns!$B$2:$B$801, 0))), "No") -> No
A11: 10 | B11: CA-2016-115812 | C11: 42530 | D11: 42535 | E11: Standard Class | F11: BH-11710 | G11: Brosina Hoffman | H11: Consumer | I11: United States | J11: Los Angeles | K11: California | L11: 90032 | M11: West | N11: OFF-AP-10002892 | O11: Office Supplies | P11: Appliances | Q11: Belkin F5C206VTEL 6 Outlet Surge | R11: 114.9 | S11: 5 | T11: 0 | U11: 34.47 | V11: =IF(M11=People!$B$2, People!$A$2, IF(M11=People!$B$3, People!$A$3, IF(M11=People!$B$4, People!$A$4, IF(M11=People!$B$5, People!$A$5, 0)))) -> Anna Andreadi | W11: =IFERROR(VLOOKUP(Orders!$B11,Returns!$B:$C,2,0),"No") -> No | X11: =IFERROR((INDEX(Returns!$C$2:$C$801, MATCH(B11, Returns!$B$2:$B$801, 0))), "No") -> No
A12: 11 | B12: CA-2016-115812 | C12: 42530 | D12: 42535 | E12: Standard Class | F12: BH-11710 | G12: Brosina Hoffman | H12: Consumer | I12: United States | J12: Los Angeles | K12: California | L12: 90032 | M12: West | N12: FUR-TA-10001539 | O12: Furniture | P12: Tables | Q12: Chromcraft Rectangular Conference Tables | R12: 1706.184 | S12: 9 | T12: 0.2 | U12: 85.3092 | V12: =IF(M12=People!$B$2, People!$A$2, IF(M12=People!$B$3, People!$A$3, IF(M12=People!$B$4, People!$A$4, IF(M12=People!$B$5, People!$A$5, 0)))) -> Anna Andreadi | W12: =IFERROR(VLOOKUP(Orders!$B12,Returns!$B:$C,2,0),"No") -> No | X12: =IFERROR((INDEX(Returns!$C$2:$C$801, MATCH(B12, Returns!$B$2:$B$801, 0))), "No") -> No
A13: 12 | B13: CA-2016-115812 | C13: 42530 | D13: 42535 | E13: Standard Class | F13: BH-11710 | G13: Brosina Hoffman | H13: Consumer | I13: United States | J13: Los Angeles | K13: California | L13: 90032 | M13: West | N13: TEC-PH-10002033 | O13: Technology | P13: Phones | Q13: Konftel 250 Conference phone - Charcoal black | R13: 911.424 | S13: 4 | T13: 0.2 | U13: 68.3568 | V13: =IF(M13=People!$B$2, People!$A$2, IF(M13=People!$B$3, People!$A$3, IF(M13=People!$B$4, People!$A$4, IF(M13=People!$B$5, People!$A$5, 0)))) -> Anna Andreadi | W13: =IFERROR(VLOOKUP(Orders!$B13,Returns!$B:$C,2,0),"No") -> No | X13: =IFERROR((INDEX(Returns!$C$2:$C$801, MATCH(B13, Returns!$B$2:$B$801, 0))), "No") -> No
... A2235: 2234 | B2235: CA-2017-123232 | C2235: 43083 | D2235: 43085 | E2235: Second Class | F2235: DJ-13630 | G2235: Doug Jacobs | H2235: Consumer | I2235: United States | J2235: Portland | K2235: Oregon | L2235: 97206 | M2235: West | N2235: TEC-PH-10001051 | O2235: Technology | P2235: Phones | Q2235: HTC One | R2235: 319.968 | S2235: 4 | T2235: 0.2 | U2235: 35.9964 | V2235: =IF(M2235=People!$B$2, People!$A$2, IF(M2235=People!$B$3, People!$A$3, IF(M2235=People!$B$4, People!$A$4, IF(M2235=People!$B$5, People!$A$5, 0)))) -> Anna Andreadi | W2235: =IFERROR(VLOOKUP(Orders!$B2235,Returns!$B:$C,2,0),"No") -> No | X2235: =IFERROR((INDEX(Returns!$C$2:$C$801, MATCH(B2235, Returns!$B$2:$B$801, 0))), "No") -> No
A2236: 2235 | B2236: CA-2019-104066 | C2236: 43804 | D2236: 43809 | E2236: Standard Class | F2236: QJ-19255 | G2236: Quincy Jones | H2236: Corporate | I2236: United States | J2236: Burlington | K2236: Vermont | M2236: East | N2236: TEC-AC-10001013 | O2236: Technology | P2236: Accessories | Q2236: Logitech ClearChat Comfort/USB Headset H390 | R2236: 205.03 | S2236: 7 | T2236: 0 | U2236: 67.6599 | V2236: =IF(M2236=People!$B$2, People!$A$2, IF(M2236=People!$B$3, People!$A$3, IF(M2236=People!$B$4, People!$A$4, IF(M2236=People!$B$5, People!$A$5, 0)))) -> Chuck Magee | W2236: =IFERROR(VLOOKUP(Orders!$B2236,Returns!$B:$C,2,0),"No") -> No | X2236: =IFERROR((INDEX(Returns!$C$2:$C$801, MATCH(B2236, Returns!$B$2:$B$801, 0))), "No") -> No
A2237: 2236 | B2237: CA-2017-145849 | C2237: 42993 | D2237: 42995 | E2237: Second Class | F2237: CT-11995 | G2237: Carol Triggs | H2237: Consumer | I2237: United States | J2237: Indianapolis | K2237: Indiana | L2237: 46203 | M2237: Central | N2237: OFF-ST-10000025 | O2237: Office Supplies | P2237: Storage | Q2237: Fellowes Stor/Drawer Steel Plus Storage Drawers | R2237: 190.86 | S2237: 2 | T2237: 0 | U2237: 11.4516 | V2237: =IF(M2237=People!$B$2, People!$A$2, IF(M2237=People!$B$3, People!$A$3, IF(M2237=People!$B$4, People!$A$4, IF(M2237=People!$B$5, People!$A$5, 0)))) -> Kelly Williams | W2237: =IFERROR(VLOOKUP(Orders!$B2237,Returns!$B:$C,2,0),"No") -> No | X2237: =IFERROR((INDEX(Returns!$C$2:$C$801, MATCH(B2237, Returns!$B$2:$B$801, 0))), "No") -> No
A2238: 2237 | B2238: CA-2017-145849 | C2238: 42993 | D2238: 42995 | E2238: Second Class | F2238: CT-11995 | G2238: Carol Triggs | H2238: Consumer | I2238: United States | J2238: Indianapolis | K2238: Indiana | L2238: 46203 | M2238: Central | N2238: OFF-AR-10000817 | O2238: Office Supplies | P2238: Art | Q2238: Manco Dry-Lighter Erasable Highlighter | R2238: 24.32 | S2238: 8 | T2238: 0 | U2238: 8.2688 | V2238: =IF(M2238=People!$B$2, People!$A$2, IF(M2238=People!$B$3, People!$A$3, IF(M2238=People!$B$4, People!$A$4, IF(M2238=People!$B$5, People!$A$5, 0)))) -> Kelly Williams | W2238: =IFERROR(VLOOKUP(Orders!$B2238,Returns!$B:$C,2,0),"No") -> No | X2238: =IFERROR((INDEX(Returns!$C$2:$C$801, MATCH(B2238, Returns!$B$2:$B$801, 0))), "No") -> No
A2239: 2238 | B2239: CA-2018-122322 | C2239: 43296 | D2239: 43302 | E2239: Standard Class | F2239: RH-19510 | G2239: Rick Huthwaite | H2239: Home Office | I2239: United States | J2239: Provo | K2239: Utah | L2239: 84604 | M2239: West | N2239: OFF-SU-10000952 | O2239: Office Supplies | P2239: Supplies | Q2239: Fiskars Home & Office Scissors | R2239: 44.4 | S2239: 5 | T2239: 0 | U2239: 12.432 | V2239: =IF(M2239=People!$B$2, People!$A$2, IF(M2239=People!$B$3, People!$A$3, IF(M2239=People!$B$4, People!$A$4, IF(M2239=People!$B$5, People!$A$5, 0)))) -> Anna Andreadi | W2239: =IFERROR(VLOOKUP(Orders!$B2239,Returns!$B:$C,2,0),"No") -> No | X2239: =IFERROR((INDEX(Returns!$C$2:$C$801, MATCH(B2239, Returns!$B$2:$B$801, 0))), "No") -> No
A2240: 2239 | B2240: CA-2019-166849 | C2240: 43575 | D2240: 43581 | E2240: Standard Class | F2240: SJ-20125 | G2240: Sanjit Jacobs | H2240: Home Office | I2240: United States | J2240: Chicago | K2240: Illinois | L2240: 60610 | M2240: Central | N2240: FUR-FU-10004597 | O2240: Furniture | P2240: Furnishings | Q2240: Eldon Cleatmat Chair Mats for Medium Pile Carpets | R2240: 44.4 | S2240: 2 | T2240: 0.6 | U2240: -52.17 | V2240: =IF(M2240=People!$B$2, People!$A$2, IF(M2240=People!$B$3, People!$A$3, IF(M2240=People!$B$4, People!$A$4, IF(M2240=People!$B$5, People!$A$5, 0)))) -> Kelly Williams | W2240: =IFERROR(VLOOKUP(Orders!$B2240,Returns!$B:$C,2,0),"No") -> No | X2240: =IFERROR((INDEX(Returns!$C$2:$C$801, MATCH(B2240, Returns!$B$2:$B$801, 0))), "No") -> No
A2241: 2240 | B2241: CA-2018-146633 | C2241: 43419 | D2241: 43421 | E2241: Second Class | F2241: TG-21310 | G2241: Toby Gnade | H2241: Consumer | I2241: United States | J2241: Los Angeles | K2241: California | L2241: 90049 | M2241: West | N2241: OFF-BI-10003527 | O2241: Office Supplies | P2241: Binders | Q2241: Fellowes PB500 Electric Punch Plastic Comb Binding Machine with Manual Bind | R2241: 1016.792 | S2241: 1 | T2241: 0.2 | U2241: 381.297 | V2241: =IF(M2241=People!$B$2, People!$A$2, IF(M2241=People!$B$3, People!$A$3, IF(M2241=People!$B$4, People!$A$4, IF(M2241=People!$B$5, People!$A$5, 0)))) -> Anna Andreadi | W2241: =IFERROR(VLOOKUP(Orders!$B2241,Returns!$B:$C,2,0),"No") -> No | X2241: =IFERROR((INDEX(Returns!$C$2:$C$801, MATCH(B2241, Returns!$B$2:$B$801, 0))), "No") -> No
A2242: 2241 | B2242: CA-2018-146633 | C2242: 43419 | D2242: 43421 | E2242: Second Class | F2242: TG-21310 | G2242: Toby Gnade | H2242: Consumer | I2242: United States | J2242: Los Angeles | K2242: California | L2242: 90049 | M2242: West | N2242: OFF-BI-10002982 | O2242: Office Supplies | P2242: Binders | Q2242: Avery Self-Adhesive Photo Pockets for Polaroid Photos | R2242: 38.136 | S2242: 7 | T2242: 0.2 | U2242: 13.3476 | V2242: =IF(M2242=People!$B$2, People!$A$2, IF(M2242=People!$B$3, People!$A$3, IF(M2242=People!$B$4, People!$A$4, IF(M2242=People!$B$5, People!$A$5, 0)))) -> Anna Andreadi | W2242: =IFERROR(VLOOKUP(Orders!$B2242,Returns!$B:$C,2,0),"No") -> No | X2242: =IFERROR((INDEX(Returns!$C$2:$C$801, MATCH(B2242, Returns!$B$2:$B$801, 0))), "No") -> No
A2243: 2242 | B2243: US-2018-126893 | C2243: 43430 | D2243: 43435 | E2243: Standard Class | F2243: CT-11995 | G2243: Carol Triggs | H2243: Consumer | I2243: United States | J2243: Philadelphia | K2243: Pennsylvania | L2243: 19134 | M2243: East | N2243: TEC-PH-10004165 | O2243: Technology | P2243: Phones | Q2243: Mitel MiVoice 5330e IP Phone | R2243: 494.982 | S2243: 3 | T2243: 0.4 | U2243: -115.4958 | V2243: =IF(M2243=People!$B$2, People!$A$2, IF(M2243=People!$B$3, People!$A$3, IF(M2243=People!$B$4, People!$A$4, IF(M2243=People!$B$5, People!$A$5, 0)))) -> Chuck Magee | W2243: =IFERROR(VLOOKUP(Orders!$B2243,Returns!$B:$C,2,0),"No") -> No | X2243: =IFERROR((INDEX(Returns!$C$2:$C$801, MATCH(B2243, Returns!$B$2:$B$801, 0))), "No") -> No
A2244: 2243 | B2244: CA-2019-103380 | C2244: 43790 | D2244: 43794 | E2244: Standard Class | F2244: BF-11005 | G2244: Barry Franz | H2244: Home Office | I2244: United States | J2244: Pasadena | K2244: California | L2244: 91104 | M2244: West | N2244: OFF-ST-10003442 | O2244: Office Supplies | P2244: Storage | Q2244: Eldon Portable Mobile Manager | R2244: 56.56 | S2244: 2 | T2244: 0 | U2244: 15.2712 | V2244: =IF(M2244=People!$B$2, People!$A$2, IF(M2244=People!$B$3, People!$A$3, IF(M2244=People!$B$4, People!$A$4, IF(M2244=People!$B$5, People!$A$5, 0)))) -> Anna Andreadi | W2244: =IFERROR(VLOOKUP(Orders!$B2244,Returns!$B:$C,2,0),"No") -> Yes | X2244: =IFERROR((INDEX(Returns!$C$2:$C$801, MATCH(B2244, Returns!$B$2:$B$801, 0))), "No") -> Yes
A2245: 2244 | B2245: CA-2019-103380 | C2245: 43790 | D2245: 43794 | E2245: Standard Class | F2245: BF-11005 | G2245: Barry Franz | H2245: Home Office | I2245: United States | J2245: Pasadena | K2245: California | L2245: 91104 | M2245: West | N2245: OFF-AR-10003856 | O2245: Office Supplies | P2245: Art | Q2245: Newell 344 | R2245: 5.56 | S2245: 2 | T2245: 0 | U2245: 1.4456 | V2245: =IF(M2245=People!$B$2, People!$A$2, IF(M2245=People!$B$3, People!$A$3, IF(M2245=People!$B$4, People!$A$4, IF(M2245=People!$B$5, People!$A$5, 0)))) -> Anna Andreadi | W2245: =IFERROR(VLOOKUP(Orders!$B2245,Returns!$B:$C,2,0),"No") -> Yes | X2245: =IFERROR((INDEX(Returns!$C$2:$C$801, MATCH(B2245, Returns!$B$2:$B$801, 0))), "No") -> Yes
A2246: 2245 | B2246: CA-2019-103380 | C2246: 43790 | D2246: 43794 | E2246: Standard Class | F2246: BF-11005 | G2246: Barry Franz | H2246: Home Office | I2246: United States | J2246: Pasadena | K2246: California | L2246: 91104 | M2246: West | N2246: OFF-FA-10004248 | O2246: Office Supplies | P2246: Fasteners | Q2246: Advantus T-Pin Paper Clips | R2246: 9.02 | S2246: 2 | T2246: 0 | U2246: 3.5178 | V2246: =IF(M2246=People!$B$2, People!$A$2, IF(M2246=People!$B$3, People!$A$3, IF(M2246=People!$B$4, People!$A$4, IF(M2246=People!$B$5, People!$A$5, 0)))) -> Anna Andreadi | W2246: =IFERROR(VLOOKUP(Orders!$B2246,Returns!$B:$C,2,0),"No") -> Yes | X2246: =IFERROR((INDEX(Returns!$C$2:$C$801, MATCH(B2246, Returns!$B$2:$B$801, 0))), "No") -> Yes
A2247: 2246 | B2247: CA-2019-103380 | C2247: 43790 | D2247: 43794 | E2247: Standard Class | F2247: BF-11005 | G2247: Barry Franz | H2247: Home Office | I2247: United States | J2247: Pasadena | K2247: California | L2247: 91104 | M2247: West | N2247: OFF-AP-10001492 | O2247: Office Supplies | P2247: Appliances | Q2247: Acco Six-Outlet Power Strip, 4' Cord Length | R2247: 8.62 | S2247: 1 | T2247: 0 | U2247: 2.2412 | V2247: =IF(M2247=People!$B$2, People!$A$2, IF(M2247=People!$B$3, People!$A$3, IF(M2247=People!$B$4, People!$A$4, IF(M2247=People!$B$5, People!$A$5, 0)))) -> Anna Andreadi | W2247: =IFERROR(VLOOKUP(Orders!$B2247,Returns!$B:$C,2,0),"No") -> Yes | X2247: =IFERROR((INDEX(Returns!$C$2:$C$801, MATCH(B2247, Returns!$B$2:$B$801, 0))), "No") -> Yes
A2248: 2247 | B2248: CA-2019-103380 | C2248: 43790 | D2248: 43794 | E2248: Standard Class | F2248: BF-11005 | G2248: Barry Franz | H2248: Home Office | I2248: United States | J2248: Pasadena | K2248: California | L2248: 91104 | M2248: West | N2248: TEC-PH-10004165 | O2248: Technology | P2248: Phones | Q2248: Mitel MiVoice 5330e IP Phone | R2248: 659.976 | S2248: 3 | T2248: 0.2 | U2248: 49.4982 | V2248: =IF(M2248=People!$B$2, People!$A$2, IF(M2248=People!$B$3, People!$A$3, IF(M2248=People!$B$4, People!$A$4, IF(M2248=People!$B$5, People!$A$5, 0)))) -> Anna Andreadi | W2248: =IFERROR(VLOOKUP(Orders!$B2248,Returns!$B:$C,2,0),"No") -> Yes | X2248: =IFERROR((INDEX(Returns!$C$2:$C$801, MATCH(B2248, Returns!$B$2:$B$801, 0))), "No") -> Yes
... A5275: 5274 | B5275: US-2018-158309 | C5275: 43430 | D5275: 43433 | E5275: First Class | F5275: PA-19060 | G5275: Pete Armstrong | H5275: Home Office | I5275: United States | J5275: Miami | K5275: Florida | L5275: 33142 | M5275: South | N5275: OFF-BI-10000145 | O5275: Office Supplies | P5275: Binders | Q5275: Zipper Ring Binder Pockets | R5275: 3.744 | S5275: 4 | T5275: 0.7 | U5275: -2.6208 | V5275: =IF(M5275=People!$B$2, People!$A$2, IF(M5275=People!$B$3, People!$A$3, IF(M5275=People!$B$4, People!$A$4, IF(M5275=People!$B$5, People!$A$5, 0)))) -> Cassandra Brandow | W5275: =IFERROR(VLOOKUP(Orders!$B5275,Returns!$B:$C,2,0),"No") -> No | X5275: =IFERROR((INDEX(Returns!$C$2:$C$801, MATCH(B5275, Returns!$B$2:$B$801, 0))), "No") -> No
A5276: 5275 | B5276: CA-2017-162887 | C5276: 43046 | D5276: 43048 | E5276: Second Class | F5276: SV-20785 | G5276: Stewart Visinsky | H5276: Consumer | I5276: United States | J5276: Burlington | K5276: Vermont | M5276: East | N5276: FUR-CH-10000595 | O5276: Furniture | P5276: Chairs | Q5276: Safco Contoured Stacking Chairs | R5276: 715.2 | S5276: 3 | T5276: 0 | U5276: 178.8 | V5276: =IF(M5276=People!$B$2, People!$A$2, IF(M5276=People!$B$3, People!$A$3, IF(M5276=People!$B$4, People!$A$4, IF(M5276=People!$B$5, People!$A$5, 0)))) -> Chuck Magee | W5276: =IFERROR(VLOOKUP(Orders!$B5276,Returns!$B:$C,2,0),"No") -> No | X5276: =IFERROR((INDEX(Returns!$C$2:$C$801, MATCH(B5276, Returns!$B$2:$B$801, 0))), "No") -> No
A5277: 5276 | B5277: CA-2019-147333 | C5277: 43813 | D5277: 43819 | E5277: Standard Class | F5277: KL-16555 | G5277: Kelly Lampkin | H5277: Corporate | I5277: United States | J5277: Fayetteville | K5277: Arkansas | L5277: 72701 | M5277: South | N5277: TEC-AC-10004469 | O5277: Technology | P5277: Accessories | Q5277: Microsoft Sculpt Comfort Mouse | R5277: 159.8 | S5277: 4 | T5277: 0 | U5277: 70.312 | V5277: =IF(M5277=People!$B$2, People!$A$2, IF(M5277=People!$B$3, People!$A$3, IF(M5277=People!$B$4, People!$A$4, IF(M5277=People!$B$5, People!$A$5, 0)))) -> Cassandra Brandow | W5277: =IFERROR(VLOOKUP(Orders!$B5277,Returns!$B:$C,2,0),"No") -> No | X5277: =IFERROR((INDEX(Returns!$C$2:$C$801, MATCH(B5277, Returns!$B$2:$B$801, 0))), "No") -> No
A5278: 5277 | B5278: CA-2019-147333 | C5278: 43813 | D5278: 43819 | E5278: Standard Class | F5278: KL-16555 | G5278: Kelly Lampkin | H5278: Corporate | I5278: United States | J5278: Fayetteville | K5278: Arkansas | L5278: 72701 | M5278: South | N5278: TEC-AC-10003038 | O5278: Technology | P5278: Accessories | Q5278: Kingston Digital DataTraveler 16GB USB 2.0 | R5278: 44.75 | S5278: 5 | T5278: 0 | U5278: 8.5025 | V5278: =IF(M5278=People!$B$2, People!$A$2, IF(M5278=People!$B$3, People!$A$3, IF(M5278=People!$B$4, People!$A$4, IF(M5278=People!$B$5, People!$A$5, 0)))) -> Cassandra Brandow | W5278: =IFERROR(VLOOKUP(Orders!$B5278,Returns!$B:$C,2,0),"No") -> No | X5278: =IFERROR((INDEX(Returns!$C$2:$C$801, MATCH(B5278, Returns!$B$2:$B$801, 0))), "No") -> No
A5279: 5278 | B5279: CA-2016-113859 | C5279: 42626 | D5279: 42630 | E5279: Standard Class | F5279: BC-11125 | G5279: Becky Castell | H5279: Home Office | I5279: United States | J5279: Odessa | K5279: Texas | L5279: 79762 | M5279: Central | N5279: FUR-CH-10004698 | O5279: Furniture | P5279: Chairs | Q5279: Padded Folding Chairs, Black, 4/Carton | R5279: 340.116 | S5279: 6 | T5279: 0.3 | U5279: -9.7176 | V5279: =IF(M5279=People!$B$2, People!$A$2, IF(M5279=People!$B$3, People!$A$3, IF(M5279=People!$B$4, People!$A$4, IF(M5279=People!$B$5, People!$A$5, 0)))) -> Kelly Williams | W5279: =IFERROR(VLOOKUP(Orders!$B5279,Returns!$B:$C,2,0),"No") -> No | X5279: =IFERROR((INDEX(Returns!$C$2:$C$801, MATCH(B5279, Returns!$B$2:$B$801, 0))), "No") -> No
A5280: 5279 | B5280: CA-2016-159681 | C5280: 42711 | D5280: 42717 | E5280: Standard Class | F5280: PO-18850 | G5280: Patrick O'Brill | H5280: Consumer | I5280: United States | J5280: Virginia Beach | K5280: Virginia | L5280: 23464 | M5280: South | N5280: OFF-PA-10003641 | O5280: Office Supplies | P5280: Paper | Q5280: Xerox 1909 | R5280: 105.52 | S5280: 4 | T5280: 0 | U5280: 48.5392 | V5280: =IF(M5280=People!$B$2, People!$A$2, IF(M5280=People!$B$3, People!$A$3, IF(M5280=People!$B$4, People!$A$4, IF(M5280=People!$B$5, People!$A$5, 0)))) -> Cassandra Brandow | W5280: =IFERROR(VLOOKUP(Orders!$B5280,Returns!$B:$C,2,0),"No") -> No | X5280: =IFERROR((INDEX(Returns!$C$2:$C$801, MATCH(B5280, Returns!$B$2:$B$801, 0))), "No") -> No
A5281: 5280 | B5281: US-2019-104094 | C5281: 43715 | D5281: 43719 | E5281: Standard Class | F5281: AG-10675 | G5281: Anna Gayman | H5281: Consumer | I5281: United States | J5281: Milwaukee | K5281: Wisconsin | L5281: 53209 | M5281: Central | N5281: TEC-AC-10002134 | O5281: Technology | P5281: Accessories | Q5281: Rosewill 107 Normal Keys USB Wired Standard Keyboard | R5281: 13.48 | S5281: 1 | T5281: 0 | U5281: 1.8872 | V5281: =IF(M5281=People!$B$2, People!$A$2, IF(M5281=People!$B$3, People!$A$3, IF(M5281=People!$B$4, People!$A$4, IF(M5281=People!$B$5, People!$A$5, 0)))) -> Kelly Williams | W5281: =IFERROR(VLOOKUP(Orders!$B5281,Returns!$B:$C,2,0),"No") -> No | X5281: =IFERROR((INDEX(Returns!$C$2:$C$801, MATCH(B5281, Returns!$B$2:$B$801, 0))), "No") -> No
A5282: 5281 | B5282: CA-2019-152709 | C5282: 43745 | D5282: 43750 | E5282: Standard Class | F5282: DB-13210 | G5282: Dean Braden | H5282: Consumer | I5282: United States | J5282: Detroit | K5282: Michigan | L5282: 48234 | M5282: Central | N5282: OFF-ST-10001837 | O5282: Office Supplies | P5282: Storage | Q5282: SAFCO Mobile Desk Side File, Wire Frame | R5282: 85.52 | S5282: 2 | T5282: 0 | U5282: 22.2352 | V5282: =IF(M5282=People!$B$2, People!$A$2, IF(M5282=People!$B$3, People!$A$3, IF(M5282=People!$B$4, People!$A$4, IF(M5282=People!$B$5, People!$A$5, 0)))) -> Kelly Williams | W5282: =IFERROR(VLOOKUP(Orders!$B5282,Returns!$B:$C,2,0),"No") -> No | X5282: =IFERROR((INDEX(Returns!$C$2:$C$801, MATCH(B5282, Returns!$B$2:$B$801, 0))), "No") -> No
A5283: 5282 | B5283: CA-2017-105158 | C5283: 42983 | D5283: 42988 | E5283: Standard Class | F5283: SP-20860 | G5283: Sung Pak | H5283: Corporate | I5283: United States | J5283: Rochester | K5283: Minnesota | L5283: 55901 | M5283: Central | N5283: FUR-FU-10001706 | O5283: Furniture | P5283: Furnishings | Q5283: Longer-Life Soft White Bulbs | R5283: 6.16 | S5283: 2 | T5283: 0 | U5283: 2.9568 | V5283: =IF(M5283=People!$B$2, People!$A$2, IF(M5283=People!$B$3, People!$A$3, IF(M5283=People!$B$4, People!$A$4, IF(M5283=People!$B$5, People!$A$5, 0)))) -> Kelly Williams | W5283: =IFERROR(VLOOKUP(Orders!$B5283,Returns!$B:$C,2,0),"No") -> Yes | X5283: =IFERROR((INDEX(Returns!$C$2:$C$801, MATCH(B5283, Returns!$B$2:$B$801, 0))), "No") -> Yes
A5284: 5283 | B5284: CA-2017-105158 | C5284: 42983 | D5284: 42988 | E5284: Standard Class | F5284: SP-20860 | G5284: Sung Pak | H5284: Corporate | I5284: United States | J5284: Rochester | K5284: Minnesota | L5284: 55901 | M5284: Central | N5284: OFF-PA-10001970 | O5284: Office Supplies | P5284: Paper | Q5284: Xerox 1881 | R5284: 36.84 | S5284: 3 | T5284: 0 | U5284: 17.3148 | V5284: =IF(M5284=People!$B$2, People!$A$2, IF(M5284=People!$B$3, People!$A$3, IF(M5284=People!$B$4, People!$A$4, IF(M5284=People!$B$5, People!$A$5, 0)))) -> Kelly Williams | W5284: =IFERROR(VLOOKUP(Orders!$B5284,Returns!$B:$C,2,0),"No") -> Yes | X5284: =IFERROR((INDEX(Returns!$C$2:$C$801, MATCH(B5284, Returns!$B$2:$B$801, 0))), "No") -> Yes
A5285: 5284 | B5285: CA-2016-133424 | C5285: 42459 | D5285: 42464 | E5285: Standard Class | F5285: Dl-13600 | G5285: Dorris liebe | H5285: Corporate | I5285: United States | J5285: Seattle | K5285: Washington | L5285: 98105 | M5285: West | N5285: OFF-ST-10002957 | O5285: Office Supplies | P5285: Storage | Q5285: Sterilite Show Offs Storage Containers | R5285: 15.84 | S5285: 3 | T5285: 0 | U5285: 0 | V5285: =IF(M5285=People!$B$2, People!$A$2, IF(M5285=People!$B$3, People!$A$3, IF(M5285=People!$B$4, People!$A$4, IF(M5285=People!$B$5, People!$A$5, 0)))) -> Anna Andreadi | W5285: =IFERROR(VLOOKUP(Orders!$B5285,Returns!$B:$C,2,0),"No") -> No | X5285: =IFERROR((INDEX(Returns!$C$2:$C$801, MATCH(B5285, Returns!$B$2:$B$801, 0))), "No") -> No
A5286: 5285 | B5286: CA-2016-133424 | C5286: 42459 | D5286: 42464 | E5286: Standard Class | F5286: Dl-13600 | G5286: Dorris liebe | H5286: Corporate | I5286: United States | J5286: Seattle | K5286: Washington | L5286: 98105 | M5286: West | N5286: OFF-LA-10002312 | O5286: Office Supplies | P5286: Labels | Q5286: Avery 490 | R5286: 44.4 | S5286: 3 | T5286: 0 | U5286: 22.2 | V5286: =IF(M5286=People!$B$2, People!$A$2, IF(M5286=People!$B$3, People!$A$3, IF(M5286=People!$B$4, People!$A$4, IF(M5286=People!$B$5, People!$A$5, 0)))) -> Anna Andreadi | W5286: =IFERROR(VLOOKUP(Orders!$B5286,Returns!$B:$C,2,0),"No") -> No | X5286: =IFERROR((INDEX(Returns!$C$2:$C$801, MATCH(B5286, Returns!$B$2:$B$801, 0))), "No") -> No
A5287: 5286 | B5287: CA-2019-105991 | C5287: 43590 | D5287: 43591 | E5287: First Class | F5287: LH-17020 | G5287: Lisa Hazard | H5287: Consumer | I5287: United States | J5287: Louisville | K5287: Colorado | L5287: 80027 | M5287: West | N5287: OFF-EN-10002600 | O5287: Office Supplies | P5287: Envelopes | Q5287: Redi-Strip #10 Envelopes, 4 1/8 x 9 1/2 | R5287: 21.24 | S5287: 9 | T5287: 0.2 | U5287: 7.434 | V5287: =IF(M5287=People!$B$2, People!$A$2, IF(M5287=People!$B$3, People!$A$3, IF(M5287=People!$B$4, People!$A$4, IF(M5287=People!$B$5, People!$A$5, 0)))) -> Anna Andreadi | W5287: =IFERROR(VLOOKUP(Orders!$B5287,Returns!$B:$C,2,0),"No") -> No | X5287: =IFERROR((INDEX(Returns!$C$2:$C$801, MATCH(B5287, Returns!$B$2:$B$801, 0))), "No") -> No
...

Sheet People
A1: Person | B1: Region
A2: Anna Andreadi | B2: West
A3: Chuck Magee | B3: East
A4: Kelly Williams | B4: Central
A5: Cassandra Brandow | B5: South

Sheet Returns
B1: Order ID | C1: Returned
B2: CA-2016-100762 | C2: Yes
B3: CA-2016-100762 | C3: Yes
B4: CA-2016-100762 | C4: Yes
B5: CA-2016-100762 | C5: Yes
B6: CA-2016-100867 | C6: Yes
B7: CA-2016-102652 | C7: Yes
B8: CA-2016-102652 | C8: Yes
B9: CA-2016-102652 | C9: Yes
B10: CA-2016-102652 | C10: Yes
B11: CA-2016-103373 | C11: Yes
B12: CA-2016-103744 | C12: Yes
... B801: US-2019-155999 | C801: Yes

Sheet Динамика доходов и прибыли
B3: Данные
A4: Названия строк | B4: Сумма по полю Sales | C4: Сумма по полю Profit
A5: 2016
A6: янв | B6: 14236.895 | C6: 2450.1907
A7: фев | B7: 4519.892 | C7: 862.3084
A8: мар | B8: 55691.009 | C8: 498.7299
A9: апр | B9: 28295.345 | C9: 3488.8352
A10: май | B10: 23648.287 | C10: 2738.7096
A11: июн | B11: 34595.128 | C11: 4976.5244
A12: июл | B12: 33946.393 | C12: -841.4826
A13: авг | B13: 27909.468 | C13: 5318.105
A14: сен | B14: 81777.351 | C14: 8328.0994
A15: окт | B15: 31453.393 | C15: 3448.2573
A16: ноя | B16: 78628.717 | C16: 9292.1269
A17: дек | B17: 69545.62 | C17: 8983.5699
A18: 2017
A19: янв | B19: 18174.076 | C19: -3281.007
A20: фев | B20: 11951.411 | C20: 2813.8508
A21: мар | B21: 38726.252 | C21: 9732.0978
A22: апр | B22: 34195.208 | C22: 4187.4962
A23: май | B23: 30131.686 | C23: 4667.869
A24: июн | B24: 24797.292 | C24: 3335.5572
A25: июл | B25: 28765.325 | C25: 3288.6483
A26: авг | B26: 36898.332 | C26: 5355.8084
A27: сен | B27: 64595.918 | C27: 8209.1627
A28: окт | B28: 31404.924 | C28: 2817.366
A29: ноя | B29: 75972.564 | C29: 12474.788
A30: дек | B30: 74919.521 | C30: 8016.9659
A31: 2018
A32: янв | B32: 18542.491 | C32: 2824.8233
A33: фев | B33: 22978.815 | C33: 5004.5795
A34: мар | B34: 51715.875 | C34: 3611.968
A35: апр | B35: 38750.039 | C35: 2977.8149
A36: май | B36: 56987.728 | C36: 8662.1464
A37: июн | B37: 40344.534 | C37: 4750.3781
A38: июл | B38: 39261.963 | C38: 4432.8779
A39: авг | B39: 31115.374 | C39: 2062.0693
A40: сен | B40: 73410.025 | C40: 9328.6576
A41: окт | B41: 59687.745 | C41: 16243.143
A42: ноя | B42: 79411.966 | C42: 4011.4075
...

Sheet Категории товаров
B1: Данные
A2: Названия строк | B2: Сумма по полю Sales | C2: Сумма по полю Profit
A3: Furniture | B3: 741999.8 | C3: 18451.273
A4: Office Supplies | B4: 719047.03 | C4: 122490.8
A5: Technology | B5: 836154.03 | C5: 145454.95
A6: Общий итог | B6: 2297200.9 | C6: 286397.02

Sheet Региональные менеджеры
B3: Данные
A4: Person | B4: Сумма по полю Sales | C4: Сумма по полю Profit
A5: Cassandra Brandow | B5: 391721.91 | C5: 46749.43
A6: Kelly Williams | B6: 501239.89 | C6: 39706.362
A7: Chuck Magee | B7: 678781.24 | C7: 91522.78
A8: Anna Andreadi | B8: 725457.82 | C8: 108418.45
A9: Общий итог | B9: 2297200.9 | C9: 286397.02

Sheet Сегменты
B3: Данные
A4: Segment | B4: Сумма по полю Sales | C4: Сумма по полю Profit
A5: Home Office | B5: 429653.15 | C5: 60298.679
A6: Corporate | B6: 706146.37 | C6: 91979.134
A7: Consumer | B7: 1161401.3 | C7: 134119.21
A8: Общий итог | B8: 2297200.9 | C8: 286397.02

Sheet Динамика сегментов
A3: Сумма по полю Sales | B3: Названия столбцов
A4: Названия строк | B4: Consumer | C4: Corporate | D4: Home Office | E4: Общий итог
A5: 2016 | B5: 266096.81 | C5: 128434.87 | D5: 89715.812 | E5: 484247.5
A6: 2017 | B6: 266535.93 | C6: 128757.31 | D6: 75239.269 | E6: 470532.51
A7: 2018 | B7: 296863.9 | C7: 207106.36 | D7: 105235.34 | E7: 609205.6
A8: 2019 | B8: 331904.7 | C8: 241847.82 | D8: 159462.73 | E8: 733215.26
A9: Общий итог | B9: 1161401.3 | C9: 706146.37 | D9: 429653.15 | E9: 2297200.9

Sheet Основные показатели
C3: Данные
A4: Годы | B4: Order Date | C4: Сумма по полю Sales | D4: Сумма по полю Profit | E4: Сумма по полю Profit ratio | F4: Среднее по полю Discount
A5: 2016 | B5: янв | C5: 14236.895 | D5: 2450.1907 | E5: 0.17210148 | F5: 0.12658228
B6: фев | C6: 4519.892 | D6: 862.3084 | E6: 0.19078075 | F6: 0.17608696
B7: мар | C7: 55691.009 | D7: 498.7299 | E7: 0.0089553037 | F7: 0.16751592
B8: апр | C8: 28295.345 | D8: 3488.8352 | E8: 0.12330068 | F8: 0.11
B9: май | C9: 23648.287 | D9: 2738.7096 | E9: 0.11581006 | F9: 0.15532787
B10: июн | C10: 34595.128 | D10: 4976.5244 | E10: 0.14385044 | F10: 0.172
B11: июл | C11: 33946.393 | D11: -841.4826 | E11: -0.024788572 | F11: 0.17167832
B12: авг | C12: 27909.468 | D12: 5318.105 | E12: 0.19054842 | F12: 0.13104575
B13: сен | C13: 81777.351 | D13: 8328.0994 | E13: 0.1018387 | F13: 0.15996269
B14: окт | C14: 31453.393 | D14: 3448.2573 | E14: 0.10963069 | F14: 0.16006289
B15: ноя | C15: 78628.717 | D15: 9292.1269 | E15: 0.11817727 | F15: 0.15116352
B16: дек | C16: 69545.62 | D16: 8983.5699 | E16: 0.12917521 | F16: 0.19082734
A17: 2017 | B17: янв | C17: 18174.076 | D17: -3281.007 | E17: -0.18053226 | F17: 0.17793103
B18: фев | C18: 11951.411 | D18: 2813.8508 | E18: 0.23544089 | F18: 0.1296875
B19: мар | C19: 38726.252 | D19: 9732.0978 | E19: 0.25130492 | F19: 0.14014493
B20: апр | C20: 34195.208 | D20: 4187.4962 | E20: 0.12245857 | F20: 0.1759375
B21: май | C21: 30131.686 | D21: 4667.869 | E21: 0.15491562 | F21: 0.16609589
B22: июн | C22: 24797.292 | D22: 3335.5572 | E22: 0.13451296 | F22: 0.17246377
B23: июл | C23: 28765.325 | D23: 3288.6483 | E23: 0.11432683 | F23: 0.17035714
B24: авг | C24: 36898.332 | D24: 5355.8084 | E24: 0.14515042 | F24: 0.15641509
B25: сен | C25: 64595.918 | D25: 8209.1627 | E25: 0.12708485 | F25: 0.14095563
B26: окт | C26: 31404.924 | D26: 2817.366 | E26: 0.089710965 | F26: 0.1623494
B27: ноя | C27: 75972.564 | D27: 12474.788 | E27: 0.16420123 | F27: 0.16231481
B28: дек | C28: 74919.521 | D28: 8016.9659 | E28: 0.1070077 | F28: 0.13724684
A29: 2018 | B29: янв | C29: 18542.491 | D29: 2824.8233 | E29: 0.15234325 | F29: 0.13258427
B30: фев | C30: 22978.815 | D30: 5004.5795 | E30: 0.21779102 | F30: 0.096385542
B31: мар | C31: 51715.875 | D31: 3611.968 | E31: 0.069842539 | F31: 0.19092025
B32: апр | C32: 38750.039 | D32: 2977.8149 | E32: 0.076846759 | F32: 0.15588235
B33: май | C33: 56987.728 | D33: 8662.1464 | E33: 0.15200021 | F33: 0.18444444
B34: июн | C34: 40344.534 | D34: 4750.3781 | E34: 0.11774527 | F34: 0.13869347
B35: июл | C35: 39261.963 | D35: 4432.8779 | E35: 0.11290515 | F35: 0.15945274
B36: авг | C36: 31115.374 | D36: 2062.0693 | E36: 0.066271718 | F36: 0.185625
B37: сен | C37: 73410.025 | D37: 9328.6576 | E37: 0.12707607 | F37: 0.14942149
B38: окт | C38: 59687.745 | D38: 16243.143 | E38: 0.2721353 | F38: 0.14719388
B39: ноя | C39: 79411.966 | D39: 4011.4075 | E39: 0.050513892 | F39: 0.15762162
B40: дек | C40: 96999.043 | D40: 17885.309 | E40: 0.18438645 | F40: 0.13542614
A41: 2019 | B41: янв | C41: 43971.374 | D41: 7140.4391 | E41: 0.16238836 | F41: 0.16129032
B42: фев | C42: 20301.133 | D42: 1613.872 | E42: 0.079496645 | F42: 0.18196262
...

Sheet Продажи по штатам
A3: Сумма по полю Sales
A4: State | B4: Итог
A5: North Dakota | B5: 919.91
A6: West Virginia | B6: 1209.824
A7: Maine | B7: 1270.53
A8: South Dakota | B8: 1315.56
A9: Wyoming | B9: 1603.136
A10: District of Columbia | B10: 2865.02
A11: Kansas | B11: 2914.31
A12: Idaho | B12: 4382.486
A13: Iowa | B13: 4579.76
A14: New Mexico | B14: 4783.522
A15: Montana | B15: 5589.352
A16: New Hampshire | B16: 7292.524
... A54: Общий итог | B54: 2297200.9

Sheet Продажи по регионам
A3: Сумма по полю Sales
A4: Region | B4: Итог
A5: Central | B5: 0.21819594
A6: East | B6: 0.29548188
A7: South | B7: 0.1705214
A8: West | B8: 0.31580078
A9: Общий итог | B9: 1

Sheet Возвраты
A3: Сумма по полю Sales
A4: Returnes | B4: Итог
A5: No | B5: 0.92142425
A6: Yes | B6: 0.078575749
A7: Общий итог | B7: 1

Sheet Дашборд
A1: SUPERSTORE SAMPLE DASHBOARD
E2: Ключевые метрики
E3: Total Sales | F3: =SUM('Основные показатели'!C5:C52) -> 2297200.9
E4: Total Profit | F4: =SUM('Основные показатели'!D5:D52) -> 286397.02
E5: Profit Ratio | F5: =F4/F3 -> 0.12467217
E6: Avg. Discount | F6: =AVERAGE('Основные показатели'!F5:F52) -> 0.15632258
